Detected binary phenotype
Traceback (most recent call last):
  File "/home/mgalactus/workspace/pyseer/venv/lib/python3.5/site-packages/pandas/io/pickle.py", line 99, in try_read
    return read_wrapper(lambda f: pkl.load(f))
  File "/home/mgalactus/workspace/pyseer/venv/lib/python3.5/site-packages/pandas/io/pickle.py", line 84, in read_wrapper
    return func(f)
  File "/home/mgalactus/workspace/pyseer/venv/lib/python3.5/site-packages/pandas/io/pickle.py", line 99, in <lambda>
    return read_wrapper(lambda f: pkl.load(f))
_pickle.UnpicklingError: invalid load key, 'A'.

During handling of the above exception, another exception occurred:

Traceback (most recent call last):
  File "/home/mgalactus/workspace/pyseer/venv/lib/python3.5/site-packages/pandas/io/pickle.py", line 104, in try_read
    lambda f: pc.load(f, encoding=encoding, compat=False))
  File "/home/mgalactus/workspace/pyseer/venv/lib/python3.5/site-packages/pandas/io/pickle.py", line 84, in read_wrapper
    return func(f)
  File "/home/mgalactus/workspace/pyseer/venv/lib/python3.5/site-packages/pandas/io/pickle.py", line 104, in <lambda>
    lambda f: pc.load(f, encoding=encoding, compat=False))
  File "/home/mgalactus/workspace/pyseer/venv/lib/python3.5/site-packages/pandas/compat/pickle_compat.py", line 194, in load
    return up.load()
  File "/usr/lib/python3.5/pickle.py", line 1043, in load
    dispatch[key[0]](self)
KeyError: 65

During handling of the above exception, another exception occurred:

Traceback (most recent call last):
  File "/home/mgalactus/workspace/pyseer/venv/lib/python3.5/site-packages/pandas/io/pickle.py", line 110, in read_pickle
    return try_read(path)
  File "/home/mgalactus/workspace/pyseer/venv/lib/python3.5/site-packages/pandas/io/pickle.py", line 108, in try_read
    lambda f: pc.load(f, encoding=encoding, compat=True))
  File "/home/mgalactus/workspace/pyseer/venv/lib/python3.5/site-packages/pandas/io/pickle.py", line 84, in read_wrapper
    return func(f)
  File "/home/mgalactus/workspace/pyseer/venv/lib/python3.5/site-packages/pandas/io/pickle.py", line 108, in <lambda>
    lambda f: pc.load(f, encoding=encoding, compat=True))
  File "/home/mgalactus/workspace/pyseer/venv/lib/python3.5/site-packages/pandas/compat/pickle_compat.py", line 194, in load
    return up.load()
  File "/usr/lib/python3.5/pickle.py", line 1043, in load
    dispatch[key[0]](self)
KeyError: 65

During handling of the above exception, another exception occurred:

Traceback (most recent call last):
  File "/home/mgalactus/workspace/pyseer/venv/lib/python3.5/site-packages/pandas/io/pickle.py", line 99, in try_read
    return read_wrapper(lambda f: pkl.load(f))
  File "/home/mgalactus/workspace/pyseer/venv/lib/python3.5/site-packages/pandas/io/pickle.py", line 84, in read_wrapper
    return func(f)
  File "/home/mgalactus/workspace/pyseer/venv/lib/python3.5/site-packages/pandas/io/pickle.py", line 99, in <lambda>
    return read_wrapper(lambda f: pkl.load(f))
_pickle.UnpicklingError: invalid load key, 'A'.

During handling of the above exception, another exception occurred:

Traceback (most recent call last):
  File "/home/mgalactus/workspace/pyseer/venv/lib/python3.5/site-packages/pandas/io/pickle.py", line 104, in try_read
    lambda f: pc.load(f, encoding=encoding, compat=False))
  File "/home/mgalactus/workspace/pyseer/venv/lib/python3.5/site-packages/pandas/io/pickle.py", line 84, in read_wrapper
    return func(f)
  File "/home/mgalactus/workspace/pyseer/venv/lib/python3.5/site-packages/pandas/io/pickle.py", line 104, in <lambda>
    lambda f: pc.load(f, encoding=encoding, compat=False))
  File "/home/mgalactus/workspace/pyseer/venv/lib/python3.5/site-packages/pandas/compat/pickle_compat.py", line 194, in load
    return up.load()
  File "/usr/lib/python3.5/pickle.py", line 1043, in load
    dispatch[key[0]](self)
KeyError: 65

During handling of the above exception, another exception occurred:

Traceback (most recent call last):
  File "../pyseer", line 580, in <module>
    m = pd.read_pickle(options.load_m)
  File "/home/mgalactus/workspace/pyseer/venv/lib/python3.5/site-packages/pandas/io/pickle.py", line 113, in read_pickle
    return try_read(path, encoding='latin1')
  File "/home/mgalactus/workspace/pyseer/venv/lib/python3.5/site-packages/pandas/io/pickle.py", line 108, in try_read
    lambda f: pc.load(f, encoding=encoding, compat=True))
  File "/home/mgalactus/workspace/pyseer/venv/lib/python3.5/site-packages/pandas/io/pickle.py", line 84, in read_wrapper
    return func(f)
  File "/home/mgalactus/workspace/pyseer/venv/lib/python3.5/site-packages/pandas/io/pickle.py", line 108, in <lambda>
    lambda f: pc.load(f, encoding=encoding, compat=True))
  File "/home/mgalactus/workspace/pyseer/venv/lib/python3.5/site-packages/pandas/compat/pickle_compat.py", line 194, in load
    return up.load()
  File "/usr/lib/python3.5/pickle.py", line 1043, in load
    dispatch[key[0]](self)
KeyError: 65
